Workbook

Sheet Data
A1: Farm ID | C1: InspectorID | D1: Village/Epiunit code | E1: Entered by | F1: Year | G1: Month | H1: Day | I1: Cattle | J1: Sheep | K1: Goats | L1: Pigs | M1: W Buffalo | N1: Cattle clin exam | O1: Cattle tested | P1: Cattle clin pos FMD | Q1: Cattle clin pos LSD | R1: Sheep clin exam | S1: Sheep clin pos FMD | T1: Sheep clin pos SGP | U1: Sheep clin pos PPR | V1: Goats clin exam | W1: Goats clin pos FMD | X1: Goats clin pos SGP | Y1: Goats clin pos PPR | Z1: Buffalo clin exam | AA1: Buffalo clin pos FMD | AB1: Buffalo clin pos LSD | AC1: Cattle tested | AD1: Cattle sero pos FMD | AE1: Cattle pos LSD | AF1: Sheep tested | AG1: Sheep smpl | AH1: Sheep sero pos FMD | AI1: Sheep test pos SGP | AJ1: Sheep sero pos PPR | AK1: Goats tested | AL1: Goats smpl | AM1: Goats sero pos FMD | AN1: Goats test pos SGP | AO1: Goat sero pos PPR | AP1: Pigs tested | AQ1: Pigs smpl | AR1: Pigs sero pos FMD | AS1: Buffalo tested | AT1: Buffalo smpl | AU1: Buffalo sero pos FMD | AV1: Buffalo test pos LSD | AW1: Wild tested | AX1: Wild smpl | AY1: Wild sero pos FMD
A2: =VLOOKUP(D2,epiunits!A$1:C$4000,2,FALSE) -> #N/A | B2: =VLOOKUP(D2,epiunits!A$1:C$4000,3,FALSE) -> #N/A | C2: =VLOOKUP(E2,Inspector!A$1:B$50,2,FALSE) -> #N/A | D2: aa | E2: aa | I2: =VLOOKUP(D2,epiunits!A$1:J$4000,6,FALSE) -> #N/A | J2: =VLOOKUP(D2,epiunits!A$1:J$4000,7,FALSE) -> #N/A | K2: =VLOOKUP(D2,epiunits!A$1:J$4000,8,FALSE) -> #N/A | L2: =VLOOKUP(D2,epiunits!A$1:J$4000,9,FALSE) -> #N/A | M2: =VLOOKUP(D2,epiunits!A$1:J$4000,10,FALSE) -> #N/A | N2: 0 | O2: 0 | P2: 0 | Q2: 0 | R2: 0 | S2: 0 | T2: 0 | U2: 0 | V2: 0 | W2: 0 | X2: 0 | Y2: 0 | Z2: 0 | AA2: 0 | AB2: 0 | AC2: 0 | AD2: 0 | AE2: 0 | AF2: 0 | AG2: 0 | AH2: 0 | AI2: 0 | AJ2: 0 | AK2: 0 | AL2: 0 | AM2: 0 | AN2: 0 | AO2: 0 | AP2: 0 | AQ2: 0 | AR2: 0 | AS2: 0 | AT2: 0 | AU2: 0 | AV2: 0 | AW2: 0 | AX2: 0 | AY2: 0
A3: =VLOOKUP(D3,epiunits!A$1:C$4000,2,FALSE) -> #N/A | B3: =VLOOKUP(D3,epiunits!A$1:C$4000,3,FALSE) -> #N/A | C3: =VLOOKUP(E3,Inspector!A$1:B$50,2,FALSE) -> #N/A | I3: =VLOOKUP(D3,epiunits!A$1:J$4000,6,FALSE) -> #N/A | J3: =VLOOKUP(D3,epiunits!A$1:J$4000,7,FALSE) -> #N/A | K3: =VLOOKUP(D3,epiunits!A$1:J$4000,8,FALSE) -> #N/A | L3: =VLOOKUP(D3,epiunits!A$1:J$4000,9,FALSE) -> #N/A | M3: =VLOOKUP(D3,epiunits!A$1:J$4000,10,FALSE) -> #N/A | N3: 0 | O3: 0 | P3: 0 | Q3: 0 | R3: 0 | S3: 0 | T3: 0 | U3: 0 | V3: 0 | W3: 0 | X3: 0 | Y3: 0 | Z3: 0 | AA3: 0 | AB3: 0 | AC3: 0 | AD3: 0 | AE3: 0 | AF3: 0 | AG3: 0 | AH3: 0 | AI3: 0 | AJ3: 0 | AK3: 0 | AL3: 0 | AM3: 0 | AN3: 0 | AO3: 0 | AP3: 0 | AQ3: 0 | AR3: 0 | AS3: 0 | AT3: 0 | AU3: 0 | AV3: 0 | AW3: 0 | AX3: 0 | AY3: 0
A4: =VLOOKUP(D4,epiunits!A$1:C$4000,2,FALSE) -> #N/A | B4: =VLOOKUP(D4,epiunits!A$1:C$4000,3,FALSE) -> #N/A | C4: =VLOOKUP(E4,Inspector!A$1:B$50,2,FALSE) -> #N/A | I4: =VLOOKUP(D4,epiunits!A$1:J$4000,6,FALSE) -> #N/A | J4: =VLOOKUP(D4,epiunits!A$1:J$4000,7,FALSE) -> #N/A | K4: =VLOOKUP(D4,epiunits!A$1:J$4000,8,FALSE) -> #N/A | L4: =VLOOKUP(D4,epiunits!A$1:J$4000,9,FALSE) -> #N/A | M4: =VLOOKUP(D4,epiunits!A$1:J$4000,10,FALSE) -> #N/A | N4: 0 | O4: 0 | P4: 0 | Q4: 0 | R4: 0 | S4: 0 | T4: 0 | U4: 0 | V4: 0 | W4: 0 | X4: 0 | Y4: 0 | Z4: 0 | AA4: 0 | AB4: 0 | AC4: 0 | AD4: 0 | AE4: 0 | AF4: 0 | AG4: 0 | AH4: 0 | AI4: 0 | AJ4: 0 | AK4: 0 | AL4: 0 | AM4: 0 | AN4: 0 | AO4: 0 | AP4: 0 | AQ4: 0 | AR4: 0 | AS4: 0 | AT4: 0 | AU4: 0 | AV4: 0 | AW4: 0 | AX4: 0 | AY4: 0
A5: =VLOOKUP(D5,epiunits!A$1:C$4000,2,FALSE) -> #N/A | B5: =VLOOKUP(D5,epiunits!A$1:C$4000,3,FALSE) -> #N/A | C5: =VLOOKUP(E5,Inspector!A$1:B$50,2,FALSE) -> #N/A | I5: =VLOOKUP(D5,epiunits!A$1:J$4000,6,FALSE) -> #N/A | J5: =VLOOKUP(D5,epiunits!A$1:J$4000,7,FALSE) -> #N/A | K5: =VLOOKUP(D5,epiunits!A$1:J$4000,8,FALSE) -> #N/A | L5: =VLOOKUP(D5,epiunits!A$1:J$4000,9,FALSE) -> #N/A | M5: =VLOOKUP(D5,epiunits!A$1:J$4000,10,FALSE) -> #N/A | N5: 0 | O5: 0 | P5: 0 | Q5: 0 | R5: 0 | S5: 0 | T5: 0 | U5: 0 | V5: 0 | W5: 0 | X5: 0 | Y5: 0 | Z5: 0 | AA5: 0 | AB5: 0 | AC5: 0 | AD5: 0 | AE5: 0 | AF5: 0 | AG5: 0 | AH5: 0 | AI5: 0 | AJ5: 0 | AK5: 0 | AL5: 0 | AM5: 0 | AN5: 0 | AO5: 0 | AP5: 0 | AQ5: 0 | AR5: 0 | AS5: 0 | AT5: 0 | AU5: 0 | AV5: 0 | AW5: 0 | AX5: 0 | AY5: 0
A6: =VLOOKUP(D6,epiunits!A$1:C$4000,2,FALSE) -> #N/A | B6: =VLOOKUP(D6,epiunits!A$1:C$4000,3,FALSE) -> #N/A | C6: =VLOOKUP(E6,Inspector!A$1:B$50,2,FALSE) -> #N/A | I6: =VLOOKUP(D6,epiunits!A$1:J$4000,6,FALSE) -> #N/A | J6: =VLOOKUP(D6,epiunits!A$1:J$4000,7,FALSE) -> #N/A | K6: =VLOOKUP(D6,epiunits!A$1:J$4000,8,FALSE) -> #N/A | L6: =VLOOKUP(D6,epiunits!A$1:J$4000,9,FALSE) -> #N/A | M6: =VLOOKUP(D6,epiunits!A$1:J$4000,10,FALSE) -> #N/A | N6: 0 | O6: 0 | P6: 0 | Q6: 0 | R6: 0 | S6: 0 | T6: 0 | U6: 0 | V6: 0 | W6: 0 | X6: 0 | Y6: 0 | Z6: 0 | AA6: 0 | AB6: 0 | AC6: 0 | AD6: 0 | AE6: 0 | AF6: 0 | AG6: 0 | AH6: 0 | AI6: 0 | AJ6: 0 | AK6: 0 | AL6: 0 | AM6: 0 | AN6: 0 | AO6: 0 | AP6: 0 | AQ6: 0 | AR6: 0 | AS6: 0 | AT6: 0 | AU6: 0 | AV6: 0 | AW6: 0 | AX6: 0 | AY6: 0
A7: =VLOOKUP(D7,epiunits!A$1:C$4000,2,FALSE) -> #N/A | B7: =VLOOKUP(D7,epiunits!A$1:C$4000,3,FALSE) -> #N/A | C7: =VLOOKUP(E7,Inspector!A$1:B$50,2,FALSE) -> #N/A | I7: =VLOOKUP(D7,epiunits!A$1:J$4000,6,FALSE) -> #N/A | J7: =VLOOKUP(D7,epiunits!A$1:J$4000,7,FALSE) -> #N/A | K7: =VLOOKUP(D7,epiunits!A$1:J$4000,8,FALSE) -> #N/A | L7: =VLOOKUP(D7,epiunits!A$1:J$4000,9,FALSE) -> #N/A | M7: =VLOOKUP(D7,epiunits!A$1:J$4000,10,FALSE) -> #N/A | N7: 0 | O7: 0 | P7: 0 | Q7: 0 | R7: 0 | S7: 0 | T7: 0 | U7: 0 | V7: 0 | W7: 0 | X7: 0 | Y7: 0 | Z7: 0 | AA7: 0 | AB7: 0 | AC7: 0 | AD7: 0 | AE7: 0 | AF7: 0 | AG7: 0 | AH7: 0 | AI7: 0 | AJ7: 0 | AK7: 0 | AL7: 0 | AM7: 0 | AN7: 0 | AO7: 0 | AP7: 0 | AQ7: 0 | AR7: 0 | AS7: 0 | AT7: 0 | AU7: 0 | AV7: 0 | AW7: 0 | AX7: 0 | AY7: 0
A8: =VLOOKUP(D8,epiunits!A$1:C$4000,2,FALSE) -> #N/A | B8: =VLOOKUP(D8,epiunits!A$1:C$4000,3,FALSE) -> #N/A | C8: =VLOOKUP(E8,Inspector!A$1:B$50,2,FALSE) -> #N/A | I8: =VLOOKUP(D8,epiunits!A$1:J$4000,6,FALSE) -> #N/A | J8: =VLOOKUP(D8,epiunits!A$1:J$4000,7,FALSE) -> #N/A | K8: =VLOOKUP(D8,epiunits!A$1:J$4000,8,FALSE) -> #N/A | L8: =VLOOKUP(D8,epiunits!A$1:J$4000,9,FALSE) -> #N/A | M8: =VLOOKUP(D8,epiunits!A$1:J$4000,10,FALSE) -> #N/A | N8: 0 | O8: 0 | P8: 0 | Q8: 0 | R8: 0 | S8: 0 | T8: 0 | U8: 0 | V8: 0 | W8: 0 | X8: 0 | Y8: 0 | Z8: 0 | AA8: 0 | AB8: 0 | AC8: 0 | AD8: 0 | AE8: 0 | AF8: 0 | AG8: 0 | AH8: 0 | AI8: 0 | AJ8: 0 | AK8: 0 | AL8: 0 | AM8: 0 | AN8: 0 | AO8: 0 | AP8: 0 | AQ8: 0 | AR8: 0 | AS8: 0 | AT8: 0 | AU8: 0 | AV8: 0 | AW8: 0 | AX8: 0 | AY8: 0
A9: =VLOOKUP(D9,epiunits!A$1:C$4000,2,FALSE) -> #N/A | B9: =VLOOKUP(D9,epiunits!A$1:C$4000,3,FALSE) -> #N/A | C9: =VLOOKUP(E9,Inspector!A$1:B$50,2,FALSE) -> #N/A | I9: =VLOOKUP(D9,epiunits!A$1:J$4000,6,FALSE) -> #N/A | J9: =VLOOKUP(D9,epiunits!A$1:J$4000,7,FALSE) -> #N/A | K9: =VLOOKUP(D9,epiunits!A$1:J$4000,8,FALSE) -> #N/A | L9: =VLOOKUP(D9,epiunits!A$1:J$4000,9,FALSE) -> #N/A | M9: =VLOOKUP(D9,epiunits!A$1:J$4000,10,FALSE) -> #N/A | N9: 0 | O9: 0 | P9: 0 | Q9: 0 | R9: 0 | S9: 0 | T9: 0 | U9: 0 | V9: 0 | W9: 0 | X9: 0 | Y9: 0 | Z9: 0 | AA9: 0 | AB9: 0 | AC9: 0 | AD9: 0 | AE9: 0 | AF9: 0 | AG9: 0 | AH9: 0 | AI9: 0 | AJ9: 0 | AK9: 0 | AL9: 0 | AM9: 0 | AN9: 0 | AO9: 0 | AP9: 0 | AQ9: 0 | AR9: 0 | AS9: 0 | AT9: 0 | AU9: 0 | AV9: 0 | AW9: 0 | AX9: 0 | AY9: 0
A10: =VLOOKUP(D10,epiunits!A$1:C$4000,2,FALSE) -> #N/A | B10: =VLOOKUP(D10,epiunits!A$1:C$4000,3,FALSE) -> #N/A | C10: =VLOOKUP(E10,Inspector!A$1:B$50,2,FALSE) -> #N/A | I10: =VLOOKUP(D10,epiunits!A$1:J$4000,6,FALSE) -> #N/A | J10: =VLOOKUP(D10,epiunits!A$1:J$4000,7,FALSE) -> #N/A | K10: =VLOOKUP(D10,epiunits!A$1:J$4000,8,FALSE) -> #N/A | L10: =VLOOKUP(D10,epiunits!A$1:J$4000,9,FALSE) -> #N/A | M10: =VLOOKUP(D10,epiunits!A$1:J$4000,10,FALSE) -> #N/A | N10: 0 | O10: 0 | P10: 0 | Q10: 0 | R10: 0 | S10: 0 | T10: 0 | U10: 0 | V10: 0 | W10: 0 | X10: 0 | Y10: 0 | Z10: 0 | AA10: 0 | AB10: 0 | AC10: 0 | AD10: 0 | AE10: 0 | AF10: 0 | AG10: 0 | AH10: 0 | AI10: 0 | AJ10: 0 | AK10: 0 | AL10: 0 | AM10: 0 | AN10: 0 | AO10: 0 | AP10: 0 | AQ10: 0 | AR10: 0 | AS10: 0 | AT10: 0 | AU10: 0 | AV10: 0 | AW10: 0 | AX10: 0 | AY10: 0
A11: =VLOOKUP(D11,epiunits!A$1:C$4000,2,FALSE) -> #N/A | B11: =VLOOKUP(D11,epiunits!A$1:C$4000,3,FALSE) -> #N/A | C11: =VLOOKUP(E11,Inspector!A$1:B$50,2,FALSE) -> #N/A | I11: =VLOOKUP(D11,epiunits!A$1:J$4000,6,FALSE) -> #N/A | J11: =VLOOKUP(D11,epiunits!A$1:J$4000,7,FALSE) -> #N/A | K11: =VLOOKUP(D11,epiunits!A$1:J$4000,8,FALSE) -> #N/A | L11: =VLOOKUP(D11,epiunits!A$1:J$4000,9,FALSE) -> #N/A | M11: =VLOOKUP(D11,epiunits!A$1:J$4000,10,FALSE) -> #N/A | N11: 0 | O11: 0 | P11: 0 | Q11: 0 | R11: 0 | S11: 0 | T11: 0 | U11: 0 | V11: 0 | W11: 0 | X11: 0 | Y11: 0 | Z11: 0 | AA11: 0 | AB11: 0 | AC11: 0 | AD11: 0 | AE11: 0 | AF11: 0 | AG11: 0 | AH11: 0 | AI11: 0 | AJ11: 0 | AK11: 0 | AL11: 0 | AM11: 0 | AN11: 0 | AO11: 0 | AP11: 0 | AQ11: 0 | AR11: 0 | AS11: 0 | AT11: 0 | AU11: 0 | AV11: 0 | AW11: 0 | AX11: 0 | AY11: 0
A12: =VLOOKUP(D12,epiunits!A$1:C$4000,2,FALSE) -> #N/A | B12: =VLOOKUP(D12,epiunits!A$1:C$4000,3,FALSE) -> #N/A | C12: =VLOOKUP(E12,Inspector!A$1:B$50,2,FALSE) -> #N/A | I12: =VLOOKUP(D12,epiunits!A$1:J$4000,6,FALSE) -> #N/A | J12: =VLOOKUP(D12,epiunits!A$1:J$4000,7,FALSE) -> #N/A | K12: =VLOOKUP(D12,epiunits!A$1:J$4000,8,FALSE) -> #N/A | L12: =VLOOKUP(D12,epiunits!A$1:J$4000,9,FALSE) -> #N/A | M12: =VLOOKUP(D12,epiunits!A$1:J$4000,10,FALSE) -> #N/A | N12: 0 | O12: 0 | P12: 0 | Q12: 0 | R12: 0 | S12: 0 | T12: 0 | U12: 0 | V12: 0 | W12: 0 | X12: 0 | Y12: 0 | Z12: 0 | AA12: 0 | AB12: 0 | AC12: 0 | AD12: 0 | AE12: 0 | AF12: 0 | AG12: 0 | AH12: 0 | AI12: 0 | AJ12: 0 | AK12: 0 | AL12: 0 | AM12: 0 | AN12: 0 | AO12: 0 | AP12: 0 | AQ12: 0 | AR12: 0 | AS12: 0 | AT12: 0 | AU12: 0 | AV12: 0 | AW12: 0 | AX12: 0 | AY12: 0
A13: =VLOOKUP(D13,epiunits!A$1:C$4000,2,FALSE) -> #N/A | B13: =VLOOKUP(D13,epiunits!A$1:C$4000,3,FALSE) -> #N/A | C13: =VLOOKUP(E13,Inspector!A$1:B$50,2,FALSE) -> #N/A | I13: =VLOOKUP(D13,epiunits!A$1:J$4000,6,FALSE) -> #N/A | J13: =VLOOKUP(D13,epiunits!A$1:J$4000,7,FALSE) -> #N/A | K13: =VLOOKUP(D13,epiunits!A$1:J$4000,8,FALSE) -> #N/A | L13: =VLOOKUP(D13,epiunits!A$1:J$4000,9,FALSE) -> #N/A | M13: =VLOOKUP(D13,epiunits!A$1:J$4000,10,FALSE) -> #N/A | N13: 0 | O13: 0 | P13: 0 | Q13: 0 | R13: 0 | S13: 0 | T13: 0 | U13: 0 | V13: 0 | W13: 0 | X13: 0 | Y13: 0 | Z13: 0 | AA13: 0 | AB13: 0 | AC13: 0 | AD13: 0 | AE13: 0 | AF13: 0 | AG13: 0 | AH13: 0 | AI13: 0 | AJ13: 0 | AK13: 0 | AL13: 0 | AM13: 0 | AN13: 0 | AO13: 0 | AP13: 0 | AQ13: 0 | AR13: 0 | AS13: 0 | AT13: 0 | AU13: 0 | AV13: 0 | AW13: 0 | AX13: 0 | AY13: 0
A14: =VLOOKUP(D14,epiunits!A$1:C$4000,2,FALSE) -> #N/A | B14: =VLOOKUP(D14,epiunits!A$1:C$4000,3,FALSE) -> #N/A | C14: =VLOOKUP(E14,Inspector!A$1:B$50,2,FALSE) -> #N/A | I14: =VLOOKUP(D14,epiunits!A$1:J$4000,6,FALSE) -> #N/A | J14: =VLOOKUP(D14,epiunits!A$1:J$4000,7,FALSE) -> #N/A | K14: =VLOOKUP(D14,epiunits!A$1:J$4000,8,FALSE) -> #N/A | L14: =VLOOKUP(D14,epiunits!A$1:J$4000,9,FALSE) -> #N/A | M14: =VLOOKUP(D14,epiunits!A$1:J$4000,10,FALSE) -> #N/A | N14: 0 | O14: 0 | P14: 0 | Q14: 0 | R14: 0 | S14: 0 | T14: 0 | U14: 0 | V14: 0 | W14: 0 | X14: 0 | Y14: 0 | Z14: 0 | AA14: 0 | AB14: 0 | AC14: 0 | AD14: 0 | AE14: 0 | AF14: 0 | AG14: 0 | AH14: 0 | AI14: 0 | AJ14: 0 | AK14: 0 | AL14: 0 | AM14: 0 | AN14: 0 | AO14: 0 | AP14: 0 | AQ14: 0 | AR14: 0 | AS14: 0 | AT14: 0 | AU14: 0 | AV14: 0 | AW14: 0 | AX14: 0 | AY14: 0
... A400: =VLOOKUP(D400,epiunits!A$1:C$4000,2,FALSE) -> #N/A | B400: =VLOOKUP(D400,epiunits!A$1:C$4000,3,FALSE) -> #N/A | C400: =VLOOKUP(E400,Inspector!A$1:B$50,2,FALSE) -> #N/A | I400: =VLOOKUP(D400,epiunits!A$1:J$4000,6,FALSE) -> #N/A | J400: =VLOOKUP(D400,epiunits!A$1:J$4000,7,FALSE) -> #N/A | K400: =VLOOKUP(D400,epiunits!A$1:J$4000,8,FALSE) -> #N/A | L400: =VLOOKUP(D400,epiunits!A$1:J$4000,9,FALSE) -> #N/A | M400: =VLOOKUP(D400,epiunits!A$1:J$4000,10,FALSE) -> #N/A | N400: 0 | O400: 0 | P400: 0 | Q400: 0 | R400: 0 | S400: 0 | T400: 0 | U400: 0 | V400: 0 | W400: 0 | X400: 0 | Y400: 0 | Z400: 0 | AA400: 0 | AB400: 0 | AC400: 0 | AD400: 0 | AE400: 0 | AF400: 0 | AG400: 0 | AH400: 0 | AI400: 0 | AJ400: 0 | AK400: 0 | AL400: 0 | AM400: 0 | AN400: 0 | AO400: 0 | AP400: 0 | AQ400: 0 | AR400: 0 | AS400: 0 | AT400: 0 | AU400: 0 | AV400: 0 | AW400: 0 | AX400: 0 | AY400: 0

Sheet epiunits
B1: 2174 | C1: KANADAS | D1: 300 | E1: 1 | F1: 0 | G1: 0 | H1: 0 | I1: 0 | J1: 0
A2: 7100006 | B2: 1061 | C2: MESIMVRIA | D2: 300 | E2: 1 | F2: 15 | G2: 0 | H2: 0 | I2: 0 | J2: 0
A3: 7100008 | B3: 1062 | C3: AMFITRITI | D3: 300 | E3: 1 | F3: 8 | G3: 0 | H3: 0 | I3: 0 | J3: 0
A4: 710001 | B4: 214 | C4: DIDYMOTEICHO | D4: 300 | E4: 1 | F4: 0 | G4: 0 | H4: 0 | I4: 1922 | J4: 0
A5: 7100011 | B5: 101 | C5: LEPROKARIA | D5: 300 | E5: 1 | F5: 3 | G5: 0 | H5: 0 | I5: 0 | J5: 0
A6: 7100014 | B6: 102 | C6: LEPROKARIA | D6: 300 | E6: 1 | F6: 10 | G6: 0 | H6: 0 | I6: 0 | J6: 0
A7: 7100016 | B7: 170 | C7: SIKORACHI | D7: 300 | E7: 1 | F7: 120 | G7: 0 | H7: 0 | I7: 0 | J7: 0
A8: 7100018 | B8: 795 | C8: GERIKO | D8: 300 | E8: 1 | F8: 25 | G8: 0 | H8: 0 | I8: 0 | J8: 0
A9: 7100020 | B9: 1063 | C9: ANTHEIA | D9: 300 | E9: 1 | F9: 130 | G9: 0 | H9: 0 | I9: 0 | J9: 0
A10: 7100022 | B10: 140 | C10: MESTI | D10: 300 | E10: 1 | F10: 45 | G10: 0 | H10: 0 | I10: 0 | J10: 0
A11: 7100026 | B11: 141 | C11: MESTI | D11: 300 | E11: 1 | F11: 31 | G11: 0 | H11: 0 | I11: 0 | J11: 0
A12: 7100027 | B12: 79 | C12: KOMAROS | D12: 300 | E12: 1 | F12: 3 | G12: 0 | H12: 0 | I12: 0 | J12: 0
A13: 710003 | B13: 215 | C13: DIDYMOTEICHO | D13: 300 | E13: 1 | F13: 0 | G13: 0 | H13: 0 | I13: 50 | J13: 0
... A77: 7100451 | B77: 862 | C77: MEGALO DEREIO | D77: 300 | E77: 1 | F77: 12 | G77: 0 | H77: 0 | I77: 0 | J77: 0
A78: 7100459 | B78: 1060 | D78: 300 | E78: 1 | F78: 11 | G78: 0 | H78: 0 | I78: 0 | J78: 0
A79: 7100470 | B79: 1192 | C79: AGRIANI | D79: 300 | E79: 1 | F79: 18 | G79: 0 | H79: 0 | I79: 0 | J79: 0
A80: 7100483 | B80: 745 | C80: AGIA MARINA | D80: 300 | E80: 1 | F80: 43 | G80: 0 | H80: 0 | I80: 0 | J80: 0
A81: 7100495 | B81: 863 | C81: MEGALO DEREIO | D81: 300 | E81: 1 | F81: 2 | G81: 150 | H81: 0 | I81: 0 | J81: 0
A82: 7100515 | B82: 979 | C82: SIDIROCHORI | D82: 300 | E82: 1 | F82: 5 | G82: 0 | H82: 0 | I82: 0 | J82: 0
A83: 7100546 | B83: 864 | C83: MEGALO DEREIO | D83: 300 | E83: 1 | F83: 2 | G83: 0 | H83: 0 | I83: 0 | J83: 0
A84: 7100552 | B84: 944 | C84: ROUSA | D84: 300 | E84: 1 | F84: 120 | G84: 0 | H84: 0 | I84: 0 | J84: 0
A85: 7100569 | B85: 1193 | C85: AGRIANI | D85: 300 | E85: 1 | F85: 32 | G85: 0 | H85: 0 | I85: 0 | J85: 0
A86: 7100573 | B86: 758 | C86: ANO MIKRAKIO | D86: 300 | E86: 1 | F86: 7 | G86: 140 | H86: 0 | I86: 0 | J86: 0
A87: 7100583 | B87: 818 | C87: GONIKO | D87: 300 | E87: 1 | F87: 22 | G87: 0 | H87: 0 | I87: 0 | J87: 0
A88: 7100589 | B88: 980 | C88: SIDIROCHORI | D88: 300 | E88: 1 | F88: 10 | G88: 0 | H88: 0 | I88: 0 | J88: 0
A89: 7100595 | B89: 746 | C89: AGIA MARINA | D89: 300 | E89: 1 | F89: 22 | G89: 262 | H89: 0 | I89: 0 | J89: 0
A90: 7100596 | B90: 895 | C90: MESIMERI | D90: 300 | E90: 1 | F90: 15 | G90: 0 | H90: 0 | I90: 0 | J90: 0
... A1077: 71304137 | B1077: 1081 | C1077: PLAKA | D1077: 300 | E1077: 1 | F1077: 0 | G1077: 15 | H1077: 0 | I1077: 0 | J1077: 0
A1078: 71304138 | B1078: 176 | D1078: 300 | E1078: 1 | F1078: 0 | G1078: 152 | H1078: 0 | I1078: 0 | J1078: 0
A1079: 71304139 | B1079: 1082 | C1079: PLAKA | D1079: 300 | E1079: 1 | F1079: 0 | G1079: 0 | H1079: 335 | I1079: 0 | J1079: 0
A1080: 71304142 | B1080: 1083 | C1080: PLAKA | D1080: 300 | E1080: 1 | F1080: 0 | G1080: 80 | H1080: 55 | I1080: 0 | J1080: 0
A1081: 71304143 | B1081: 1084 | C1081: PLAKA | D1081: 300 | E1081: 1 | F1081: 0 | G1081: 40 | H1081: 30 | I1081: 0 | J1081: 0
A1082: 71304147 | B1082: 1085 | C1082: PLAKA | D1082: 300 | E1082: 1 | F1082: 0 | G1082: 0 | H1082: 40 | I1082: 0 | J1082: 0
A1083: 71304148 | B1083: 1086 | C1083: PLAKA | D1083: 300 | E1083: 1 | F1083: 0 | G1083: 0 | H1083: 230 | I1083: 0 | J1083: 0
A1084: 71304149 | B1084: 1087 | C1084: PLAKA | D1084: 300 | E1084: 1 | F1084: 0 | G1084: 70 | H1084: 0 | I1084: 0 | J1084: 0
A1085: 71304151 | B1085: 1088 | C1085: PLAKA | D1085: 300 | E1085: 1 | F1085: 0 | G1085: 55 | H1085: 0 | I1085: 0 | J1085: 0
A1086: 71304157 | B1086: 77 | C1086: KIRKI | D1086: 300 | E1086: 1 | F1086: 0 | G1086: 0 | H1086: 70 | I1086: 0 | J1086: 0
A1087: 71304160 | B1087: 171 | C1087: SIKORACHI | D1087: 300 | E1087: 1 | F1087: 0 | G1087: 0 | H1087: 290 | I1087: 0 | J1087: 0
A1088: 71304161 | B1088: 172 | C1088: SIKORACHI | D1088: 300 | E1088: 1 | F1088: 0 | G1088: 0 | H1088: 290 | I1088: 0 | J1088: 0
A1089: 71304164 | B1089: 173 | C1089: SIKORACHI | D1089: 300 | E1089: 1 | F1089: 0 | G1089: 0 | H1089: 300 | I1089: 0 | J1089: 0
...

Sheet Inspector
A1: ARIS EXAKOIDIS | B1: 1
A2: CHRISTINA FOUKI | B2: 2
